Watching for file changes with StatReloader
C:\Users\pheva\Desktop\dj\AK_HR\hr\account\api\ses.py changed, reloading.
Watching for file changes with StatReloader
Internal Server Error: /api/v1/auth/password-reset
Traceback (most recent call last):
  File "C:\Users\pheva\Desktop\dj\AK_HR\hr\v\Lib\site-packages\django\core\handlers\exception.py", line 55, in inner
    response = get_response(request)
  File "C:\Users\pheva\Desktop\dj\AK_HR\hr\v\Lib\site-packages\django\core\handlers\base.py", line 197, in _get_response
    response = wrapped_callback(request, *callback_args, **callback_kwargs)
  File "C:\Users\pheva\Desktop\dj\AK_HR\hr\v\Lib\site-packages\django\views\decorators\csrf.py", line 56, in wrapper_view
    return view_func(*args, **kwargs)
  File "C:\Users\pheva\Desktop\dj\AK_HR\hr\v\Lib\site-packages\django\views\generic\base.py", line 104, in view
    return self.dispatch(request, *args, **kwargs)
           ~~~~~~~~~~~~~^^^^^^^^^^^^^^^^^^^^^^^^^^
  File "C:\Users\pheva\Desktop\dj\AK_HR\hr\v\Lib\site-packages\rest_framework\views.py", line 515, in dispatch
    response = self.handle_exception(exc)
  File "C:\Users\pheva\Desktop\dj\AK_HR\hr\v\Lib\site-packages\rest_framework\views.py", line 475, in handle_exception
    self.raise_uncaught_exception(exc)
    ~~~~~~~~~~~~~~~~~~~~~~~~~~~~~^^^^^
  File "C:\Users\pheva\Desktop\dj\AK_HR\hr\v\Lib\site-packages\rest_framework\views.py", line 486, in raise_uncaught_exception
    raise exc
  File "C:\Users\pheva\Desktop\dj\AK_HR\hr\v\Lib\site-packages\rest_framework\views.py", line 512, in dispatch
    response = handler(request, *args, **kwargs)
  File "C:\Users\pheva\Desktop\dj\AK_HR\hr\account\api\views.py", line 121, in post
    if serializer.is_valid():
       ~~~~~~~~~~~~~~~~~~~^^
  File "C:\Users\pheva\Desktop\dj\AK_HR\hr\v\Lib\site-packages\rest_framework\serializers.py", line 225, in is_valid
    self._validated_data = self.run_validation(self.initial_data)
                           ~~~~~~~~~~~~~~~~~~~^^^^^^^^^^^^^^^^^^^
  File "C:\Users\pheva\Desktop\dj\AK_HR\hr\v\Lib\site-packages\rest_framework\serializers.py", line 444, in run_validation
    value = self.to_internal_value(data)
  File "C:\Users\pheva\Desktop\dj\AK_HR\hr\v\Lib\site-packages\rest_framework\serializers.py", line 503, in to_internal_value
    validated_value = validate_method(validated_value)
  File "C:\Users\pheva\Desktop\dj\AK_HR\hr\account\api\ses.py", line 210, in validate_email
    User.objects.get(email=value)
    ^^^^^^^^^^^^
  File "C:\Users\pheva\Desktop\dj\AK_HR\hr\v\Lib\site-packages\django\db\models\manager.py", line 196, in __get__
    raise AttributeError(
    ...<5 lines>...
    )
AttributeError: Manager isn't available; 'auth.User' has been swapped for 'account.User'
C:\Users\pheva\Desktop\dj\AK_HR\hr\account\api\ses.py changed, reloading.
Watching for file changes with StatReloader
C:\Users\pheva\Desktop\dj\AK_HR\hr\account\api\ses.py changed, reloading.
Watching for file changes with StatReloader
C:\Users\pheva\Desktop\dj\AK_HR\hr\account\api\ses.py changed, reloading.
Watching for file changes with StatReloader
Internal Server Error: /
Traceback (most recent call last):
  File "C:\Users\pheva\Desktop\dj\AK_HR\hr\v\Lib\site-packages\django\core\handlers\exception.py", line 55, in inner
    response = get_response(request)
  File "C:\Users\pheva\Desktop\dj\AK_HR\hr\v\Lib\site-packages\django\core\handlers\base.py", line 197, in _get_response
    response = wrapped_callback(request, *callback_args, **callback_kwargs)
  File "C:\Users\pheva\Desktop\dj\AK_HR\hr\account\views.py", line 21, in display_login_page
    return render(request, "registration/login.html", context)
  File "C:\Users\pheva\Desktop\dj\AK_HR\hr\v\Lib\site-packages\django\shortcuts.py", line 24, in render
    content = loader.render_to_string(template_name, context, request, using=using)
  File "C:\Users\pheva\Desktop\dj\AK_HR\hr\v\Lib\site-packages\django\template\loader.py", line 61, in render_to_string
    template = get_template(template_name, using=using)
  File "C:\Users\pheva\Desktop\dj\AK_HR\hr\v\Lib\site-packages\django\template\loader.py", line 19, in get_template
    raise TemplateDoesNotExist(template_name, chain=chain)
django.template.exceptions.TemplateDoesNotExist: registration/login.html
Not Found: /favicon.ico
Not Found: /api/v1/auth/password-reset/confirm
Not Found: /api/v1/auth/password-reset/confirm
C:\Users\pheva\Desktop\dj\AK_HR\hr\A_sys\urls.py changed, reloading.
Watching for file changes with StatReloader
Bad Request: /api/v1/auth/login
Bad Request: /api/v1/auth/login
Internal Server Error: /api/v1/auth/login
Traceback (most recent call last):
  File "C:\Users\pheva\Desktop\dj\AK_HR\hr\v\Lib\site-packages\django\db\backends\base\base.py", line 289, in ensure_connection
    self.connect()
    ~~~~~~~~~~~~^^
  File "C:\Users\pheva\Desktop\dj\AK_HR\hr\v\Lib\site-packages\django\utils\asyncio.py", line 26, in inner
    return func(*args, **kwargs)
  File "C:\Users\pheva\Desktop\dj\AK_HR\hr\v\Lib\site-packages\django\db\backends\base\base.py", line 270, in connect
    self.connection = self.get_new_connection(conn_params)
                      ~~~~~~~~~~~~~~~~~~~~~~~^^^^^^^^^^^^^
  File "C:\Users\pheva\Desktop\dj\AK_HR\hr\v\Lib\site-packages\django\utils\asyncio.py", line 26, in inner
    return func(*args, **kwargs)
  File "C:\Users\pheva\Desktop\dj\AK_HR\hr\v\Lib\site-packages\django\db\backends\postgresql\base.py", line 269, in get_new_connection
    connection = self.Database.connect(**conn_params)
  File "C:\Users\pheva\Desktop\dj\AK_HR\hr\v\Lib\site-packages\psycopg2\__init__.py", line 135, in connect
    conn = _connect(dsn, connection_factory=connection_factory, **kwasync)
psycopg2.OperationalError: could not translate host name "9qasp5v56q8ckkf5dc.leapcellpool.com" to address: Name or service not known


The above exception was the direct cause of the following exception:

Traceback (most recent call last):
  File "C:\Users\pheva\Desktop\dj\AK_HR\hr\v\Lib\site-packages\django\core\handlers\exception.py", line 55, in inner
    response = get_response(request)
  File "C:\Users\pheva\Desktop\dj\AK_HR\hr\v\Lib\site-packages\django\core\handlers\base.py", line 197, in _get_response
    response = wrapped_callback(request, *callback_args, **callback_kwargs)
  File "C:\Users\pheva\Desktop\dj\AK_HR\hr\v\Lib\site-packages\django\views\decorators\csrf.py", line 56, in wrapper_view
    return view_func(*args, **kwargs)
  File "C:\Users\pheva\Desktop\dj\AK_HR\hr\v\Lib\site-packages\django\views\generic\base.py", line 104, in view
    return self.dispatch(request, *args, **kwargs)
           ~~~~~~~~~~~~~^^^^^^^^^^^^^^^^^^^^^^^^^^
  File "C:\Users\pheva\Desktop\dj\AK_HR\hr\v\Lib\site-packages\rest_framework\views.py", line 515, in dispatch
    response = self.handle_exception(exc)
  File "C:\Users\pheva\Desktop\dj\AK_HR\hr\v\Lib\site-packages\rest_framework\views.py", line 475, in handle_exception
    self.raise_uncaught_exception(exc)
    ~~~~~~~~~~~~~~~~~~~~~~~~~~~~~^^^^^
  File "C:\Users\pheva\Desktop\dj\AK_HR\hr\v\Lib\site-packages\rest_framework\views.py", line 486, in raise_uncaught_exception
    raise exc
  File "C:\Users\pheva\Desktop\dj\AK_HR\hr\v\Lib\site-packages\rest_framework\views.py", line 512, in dispatch
    response = handler(request, *args, **kwargs)
  File "C:\Users\pheva\Desktop\dj\AK_HR\hr\account\api\views.py", line 35, in post
    serializer.is_valid(raise_exception=True)
    ~~~~~~~~~~~~~~~~~~~^^^^^^^^^^^^^^^^^^^^^^
  File "C:\Users\pheva\Desktop\dj\AK_HR\hr\v\Lib\site-packages\rest_framework\serializers.py", line 225, in is_valid
    self._validated_data = self.run_validation(self.initial_data)
                           ~~~~~~~~~~~~~~~~~~~^^^^^^^^^^^^^^^^^^^
  File "C:\Users\pheva\Desktop\dj\AK_HR\hr\v\Lib\site-packages\rest_framework\serializers.py", line 447, in run_validation
    value = self.validate(value)
  File "C:\Users\pheva\Desktop\dj\AK_HR\hr\account\api\ses.py", line 90, in validate
    user = authenticate(user_id=user_ID, password=password)
  File "C:\Users\pheva\Desktop\dj\AK_HR\hr\v\Lib\site-packages\django\views\decorators\debug.py", line 42, in sensitive_variables_wrapper
    return func(*func_args, **func_kwargs)
  File "C:\Users\pheva\Desktop\dj\AK_HR\hr\v\Lib\site-packages\django\contrib\auth\__init__.py", line 77, in authenticate
    user = backend.authenticate(request, **credentials)
  File "C:\Users\pheva\Desktop\dj\AK_HR\hr\v\Lib\site-packages\django\contrib\auth\backends.py", line 46, in authenticate
    user = UserModel._default_manager.get_by_natural_key(username)
  File "C:\Users\pheva\Desktop\dj\AK_HR\hr\v\Lib\site-packages\django\contrib\auth\base_user.py", line 54, in get_by_natural_key
    return self.get(**{self.model.USERNAME_FIELD: username})
           ~~~~~~~~^^^^^^^^^^^^^^^^^^^^^^^^^^^^^^^^^^^^^^^^^
  File "C:\Users\pheva\Desktop\dj\AK_HR\hr\v\Lib\site-packages\django\db\models\manager.py", line 87, in manager_method
    return getattr(self.get_queryset(), name)(*args, **kwargs)
           ~~~~~~~~~~~~~~~~~~~~~~~~~~~~~~~~~~^^^^^^^^^^^^^^^^^
  File "C:\Users\pheva\Desktop\dj\AK_HR\hr\v\Lib\site-packages\django\db\models\query.py", line 633, in get
    num = len(clone)
  File "C:\Users\pheva\Desktop\dj\AK_HR\hr\v\Lib\site-packages\django\db\models\query.py", line 380, in __len__
    self._fetch_all()
    ~~~~~~~~~~~~~~~^^
  File "C:\Users\pheva\Desktop\dj\AK_HR\hr\v\Lib\site-packages\django\db\models\query.py", line 1881, in _fetch_all
    self._result_cache = list(self._iterable_class(self))
                         ~~~~^^^^^^^^^^^^^^^^^^^^^^^^^^^^
  File "C:\Users\pheva\Desktop\dj\AK_HR\hr\v\Lib\site-packages\django\db\models\query.py", line 91, in __iter__
    results = compiler.execute_sql(
        chunked_fetch=self.chunked_fetch, chunk_size=self.chunk_size
    )
  File "C:\Users\pheva\Desktop\dj\AK_HR\hr\v\Lib\site-packages\django\db\models\sql\compiler.py", line 1558, in execute_sql
    cursor = self.connection.cursor()
  File "C:\Users\pheva\Desktop\dj\AK_HR\hr\v\Lib\site-packages\django\utils\asyncio.py", line 26, in inner
    return func(*args, **kwargs)
  File "C:\Users\pheva\Desktop\dj\AK_HR\hr\v\Lib\site-packages\django\db\backends\base\base.py", line 330, in cursor
    return self._cursor()
           ~~~~~~~~~~~~^^
  File "C:\Users\pheva\Desktop\dj\AK_HR\hr\v\Lib\site-packages\django\db\backends\base\base.py", line 306, in _cursor
    self.ensure_connection()
    ~~~~~~~~~~~~~~~~~~~~~~^^
  File "C:\Users\pheva\Desktop\dj\AK_HR\hr\v\Lib\site-packages\django\utils\asyncio.py", line 26, in inner
    return func(*args, **kwargs)
  File "C:\Users\pheva\Desktop\dj\AK_HR\hr\v\Lib\site-packages\django\db\backends\base\base.py", line 288, in ensure_connection
    with self.wrap_database_errors:
         ^^^^^^^^^^^^^^^^^^^^^^^^^
  File "C:\Users\pheva\Desktop\dj\AK_HR\hr\v\Lib\site-packages\django\db\utils.py", line 91, in __exit__
    raise dj_exc_value.with_traceback(traceback) from exc_value
  File "C:\Users\pheva\Desktop\dj\AK_HR\hr\v\Lib\site-packages\django\db\backends\base\base.py", line 289, in ensure_connection
    self.connect()
    ~~~~~~~~~~~~^^
  File "C:\Users\pheva\Desktop\dj\AK_HR\hr\v\Lib\site-packages\django\utils\asyncio.py", line 26, in inner
    return func(*args, **kwargs)
  File "C:\Users\pheva\Desktop\dj\AK_HR\hr\v\Lib\site-packages\django\db\backends\base\base.py", line 270, in connect
    self.connection = self.get_new_connection(conn_params)
                      ~~~~~~~~~~~~~~~~~~~~~~~^^^^^^^^^^^^^
  File "C:\Users\pheva\Desktop\dj\AK_HR\hr\v\Lib\site-packages\django\utils\asyncio.py", line 26, in inner
    return func(*args, **kwargs)
  File "C:\Users\pheva\Desktop\dj\AK_HR\hr\v\Lib\site-packages\django\db\backends\postgresql\base.py", line 269, in get_new_connection
    connection = self.Database.connect(**conn_params)
  File "C:\Users\pheva\Desktop\dj\AK_HR\hr\v\Lib\site-packages\psycopg2\__init__.py", line 135, in connect
    conn = _connect(dsn, connection_factory=connection_factory, **kwasync)
django.db.utils.OperationalError: could not translate host name "9qasp5v56q8ckkf5dc.leapcellpool.com" to address: Name or service not known

Internal Server Error: /api/v1/auth/login
Traceback (most recent call last):
  File "C:\Users\pheva\Desktop\dj\AK_HR\hr\v\Lib\site-packages\django\db\backends\base\base.py", line 289, in ensure_connection
    self.connect()
    ~~~~~~~~~~~~^^
  File "C:\Users\pheva\Desktop\dj\AK_HR\hr\v\Lib\site-packages\django\utils\asyncio.py", line 26, in inner
    return func(*args, **kwargs)
  File "C:\Users\pheva\Desktop\dj\AK_HR\hr\v\Lib\site-packages\django\db\backends\base\base.py", line 270, in connect
    self.connection = self.get_new_connection(conn_params)
                      ~~~~~~~~~~~~~~~~~~~~~~~^^^^^^^^^^^^^
  File "C:\Users\pheva\Desktop\dj\AK_HR\hr\v\Lib\site-packages\django\utils\asyncio.py", line 26, in inner
    return func(*args, **kwargs)
  File "C:\Users\pheva\Desktop\dj\AK_HR\hr\v\Lib\site-packages\django\db\backends\postgresql\base.py", line 269, in get_new_connection
    connection = self.Database.connect(**conn_params)
  File "C:\Users\pheva\Desktop\dj\AK_HR\hr\v\Lib\site-packages\psycopg2\__init__.py", line 135, in connect
    conn = _connect(dsn, connection_factory=connection_factory, **kwasync)
psycopg2.OperationalError: could not translate host name "9qasp5v56q8ckkf5dc.leapcellpool.com" to address: Name or service not known


The above exception was the direct cause of the following exception:

Traceback (most recent call last):
  File "C:\Users\pheva\Desktop\dj\AK_HR\hr\v\Lib\site-packages\django\core\handlers\exception.py", line 55, in inner
    response = get_response(request)
  File "C:\Users\pheva\Desktop\dj\AK_HR\hr\v\Lib\site-packages\django\core\handlers\base.py", line 197, in _get_response
    response = wrapped_callback(request, *callback_args, **callback_kwargs)
  File "C:\Users\pheva\Desktop\dj\AK_HR\hr\v\Lib\site-packages\django\views\decorators\csrf.py", line 56, in wrapper_view
    return view_func(*args, **kwargs)
  File "C:\Users\pheva\Desktop\dj\AK_HR\hr\v\Lib\site-packages\django\views\generic\base.py", line 104, in view
    return self.dispatch(request, *args, **kwargs)
           ~~~~~~~~~~~~~^^^^^^^^^^^^^^^^^^^^^^^^^^
  File "C:\Users\pheva\Desktop\dj\AK_HR\hr\v\Lib\site-packages\rest_framework\views.py", line 515, in dispatch
    response = self.handle_exception(exc)
  File "C:\Users\pheva\Desktop\dj\AK_HR\hr\v\Lib\site-packages\rest_framework\views.py", line 475, in handle_exception
    self.raise_uncaught_exception(exc)
    ~~~~~~~~~~~~~~~~~~~~~~~~~~~~~^^^^^
  File "C:\Users\pheva\Desktop\dj\AK_HR\hr\v\Lib\site-packages\rest_framework\views.py", line 486, in raise_uncaught_exception
    raise exc
  File "C:\Users\pheva\Desktop\dj\AK_HR\hr\v\Lib\site-packages\rest_framework\views.py", line 512, in dispatch
    response = handler(request, *args, **kwargs)
  File "C:\Users\pheva\Desktop\dj\AK_HR\hr\account\api\views.py", line 35, in post
    serializer.is_valid(raise_exception=True)
    ~~~~~~~~~~~~~~~~~~~^^^^^^^^^^^^^^^^^^^^^^
  File "C:\Users\pheva\Desktop\dj\AK_HR\hr\v\Lib\site-packages\rest_framework\serializers.py", line 225, in is_valid
    self._validated_data = self.run_validation(self.initial_data)
                           ~~~~~~~~~~~~~~~~~~~^^^^^^^^^^^^^^^^^^^
  File "C:\Users\pheva\Desktop\dj\AK_HR\hr\v\Lib\site-packages\rest_framework\serializers.py", line 447, in run_validation
    value = self.validate(value)
  File "C:\Users\pheva\Desktop\dj\AK_HR\hr\account\api\ses.py", line 90, in validate
    user = authenticate(user_id=user_ID, password=password)
  File "C:\Users\pheva\Desktop\dj\AK_HR\hr\v\Lib\site-packages\django\views\decorators\debug.py", line 42, in sensitive_variables_wrapper
    return func(*func_args, **func_kwargs)
  File "C:\Users\pheva\Desktop\dj\AK_HR\hr\v\Lib\site-packages\django\contrib\auth\__init__.py", line 77, in authenticate
    user = backend.authenticate(request, **credentials)
  File "C:\Users\pheva\Desktop\dj\AK_HR\hr\v\Lib\site-packages\django\contrib\auth\backends.py", line 46, in authenticate
    user = UserModel._default_manager.get_by_natural_key(username)
  File "C:\Users\pheva\Desktop\dj\AK_HR\hr\v\Lib\site-packages\django\contrib\auth\base_user.py", line 54, in get_by_natural_key
    return self.get(**{self.model.USERNAME_FIELD: username})
           ~~~~~~~~^^^^^^^^^^^^^^^^^^^^^^^^^^^^^^^^^^^^^^^^^
  File "C:\Users\pheva\Desktop\dj\AK_HR\hr\v\Lib\site-packages\django\db\models\manager.py", line 87, in manager_method
    return getattr(self.get_queryset(), name)(*args, **kwargs)
           ~~~~~~~~~~~~~~~~~~~~~~~~~~~~~~~~~~^^^^^^^^^^^^^^^^^
  File "C:\Users\pheva\Desktop\dj\AK_HR\hr\v\Lib\site-packages\django\db\models\query.py", line 633, in get
    num = len(clone)
  File "C:\Users\pheva\Desktop\dj\AK_HR\hr\v\Lib\site-packages\django\db\models\query.py", line 380, in __len__
    self._fetch_all()
    ~~~~~~~~~~~~~~~^^
  File "C:\Users\pheva\Desktop\dj\AK_HR\hr\v\Lib\site-packages\django\db\models\query.py", line 1881, in _fetch_all
    self._result_cache = list(self._iterable_class(self))
                         ~~~~^^^^^^^^^^^^^^^^^^^^^^^^^^^^
  File "C:\Users\pheva\Desktop\dj\AK_HR\hr\v\Lib\site-packages\django\db\models\query.py", line 91, in __iter__
    results = compiler.execute_sql(
        chunked_fetch=self.chunked_fetch, chunk_size=self.chunk_size
    )
  File "C:\Users\pheva\Desktop\dj\AK_HR\hr\v\Lib\site-packages\django\db\models\sql\compiler.py", line 1558, in execute_sql
    cursor = self.connection.cursor()
  File "C:\Users\pheva\Desktop\dj\AK_HR\hr\v\Lib\site-packages\django\utils\asyncio.py", line 26, in inner
    return func(*args, **kwargs)
  File "C:\Users\pheva\Desktop\dj\AK_HR\hr\v\Lib\site-packages\django\db\backends\base\base.py", line 330, in cursor
    return self._cursor()
           ~~~~~~~~~~~~^^
  File "C:\Users\pheva\Desktop\dj\AK_HR\hr\v\Lib\site-packages\django\db\backends\base\base.py", line 306, in _cursor
    self.ensure_connection()
    ~~~~~~~~~~~~~~~~~~~~~~^^
  File "C:\Users\pheva\Desktop\dj\AK_HR\hr\v\Lib\site-packages\django\utils\asyncio.py", line 26, in inner
    return func(*args, **kwargs)
  File "C:\Users\pheva\Desktop\dj\AK_HR\hr\v\Lib\site-packages\django\db\backends\base\base.py", line 288, in ensure_connection
    with self.wrap_database_errors:
         ^^^^^^^^^^^^^^^^^^^^^^^^^
  File "C:\Users\pheva\Desktop\dj\AK_HR\hr\v\Lib\site-packages\django\db\utils.py", line 91, in __exit__
    raise dj_exc_value.with_traceback(traceback) from exc_value
  File "C:\Users\pheva\Desktop\dj\AK_HR\hr\v\Lib\site-packages\django\db\backends\base\base.py", line 289, in ensure_connection
    self.connect()
    ~~~~~~~~~~~~^^
  File "C:\Users\pheva\Desktop\dj\AK_HR\hr\v\Lib\site-packages\django\utils\asyncio.py", line 26, in inner
    return func(*args, **kwargs)
  File "C:\Users\pheva\Desktop\dj\AK_HR\hr\v\Lib\site-packages\django\db\backends\base\base.py", line 270, in connect
    self.connection = self.get_new_connection(conn_params)
                      ~~~~~~~~~~~~~~~~~~~~~~~^^^^^^^^^^^^^
  File "C:\Users\pheva\Desktop\dj\AK_HR\hr\v\Lib\site-packages\django\utils\asyncio.py", line 26, in inner
    return func(*args, **kwargs)
  File "C:\Users\pheva\Desktop\dj\AK_HR\hr\v\Lib\site-packages\django\db\backends\postgresql\base.py", line 269, in get_new_connection
    connection = self.Database.connect(**conn_params)
  File "C:\Users\pheva\Desktop\dj\AK_HR\hr\v\Lib\site-packages\psycopg2\__init__.py", line 135, in connect
    conn = _connect(dsn, connection_factory=connection_factory, **kwasync)
django.db.utils.OperationalError: could not translate host name "9qasp5v56q8ckkf5dc.leapcellpool.com" to address: Name or service not known

Bad Request: /api/v1/auth/login
C:\Users\pheva\Desktop\dj\AK_HR\hr\account\api\ses.py changed, reloading.
Watching for file changes with StatReloader
C:\Users\pheva\Desktop\dj\AK_HR\hr\account\api\views.py changed, reloading.
Watching for file changes with StatReloader
